=== RUN  TestErrorf
Exception: {
	__self__ : 0x2982, 
	__type__ : {
		gt : named(stdgo._internal.math.bits.Bits_T_errorString.T_errorString,[error: {
	get : <function>
},runtimeError: {
	get : <function>
}],basic(17),false,{
				get : <function>
			})
	}
}
Called from module gt : named(stdgo._internal.math.bits.Bits_T_errorString.T_errorString,[error: {
Called from module get : <function>
Called from module },runtimeError: {
Called from module get : <function>
Called from module }],basic(17),false,{
Called from module get : <function>
Called from module })
Called from module }
Called from module }
Called from .new haxe_ValueException (/home/runner/work/go2hx/go2hx/golibs/std_fmt.js line 29322 column 17)
Called from haxe_Exception.thrown (/home/runner/work/go2hx/go2hx/golibs/std_fmt.js line 29252 column 11)
Called from stdgo_AnyInterface.equals (/home/runner/work/go2hx/go2hx/golibs/std_fmt.js line 28440 column 24)
Called from .stdgo__$internal_reflect_Reflect_$deepEqual_deepEqual (/home/runner/work/go2hx/go2hx/golibs/std_fmt.js line 42347 column 29)
Called from module at stdgo__$internal_testing_InternalTest._$internal_fmt_$test_Fmt_$test_$testErrorf_testErrorf [as f] (/home/runner/work/go2hx/go2hx/golibs/std_fmt.js:41288:7)
Called from stdgo__$internal_testing_M_$static_$extension.run (/home/runner/work/go2hx/go2hx/golibs/std_fmt.js line 86717 column 9)
Called from ._$internal_fmt_$dot_$test_Fmt_$dot_$test_main (/home/runner/work/go2hx/go2hx/golibs/std_fmt.js line 76751 column 59)
Called from module at /home/runner/work/go2hx/go2hx/golibs/std_fmt.js:106374:1
Called from module at Object.<anonymous> (/home/runner/work/go2hx/go2hx/golibs/std_fmt.js:106375:3)
Called from Module._compile (node:internal/modules/cjs/loader line 1469 column 14)

-- FAIL: TestErrorf (0.054000139236450195)
